Internal Server Error: /back_end/basic_data/
Traceback (most recent call last):
  File "/usr/local/lib/python3.6/dist-packages/django/db/backends/base/base.py", line 216, in ensure_connection
    self.connect()
  File "/usr/local/lib/python3.6/dist-packages/django/db/backends/base/base.py", line 194, in connect
    self.connection = self.get_new_connection(conn_params)
  File "/usr/local/lib/python3.6/dist-packages/django/db/backends/postgresql/base.py", line 178, in get_new_connection
    connection = Database.connect(**conn_params)
  File "/usr/lib/python3/dist-packages/psycopg2/__init__.py", line 130, in connect
    conn = _connect(dsn, connection_factory=connection_factory, **kwasync)
psycopg2.OperationalError: fe_sendauth: no password supplied


The above exception was the direct cause of the following exception:

Traceback (most recent call last):
  File "/usr/local/lib/python3.6/dist-packages/django/core/handlers/exception.py", line 34, in inner
    response = get_response(request)
  File "/usr/local/lib/python3.6/dist-packages/django/core/handlers/base.py", line 126, in _get_response
    response = self.process_exception_by_middleware(e, request)
  File "/usr/local/lib/python3.6/dist-packages/django/core/handlers/base.py", line 124, in _get_response
    response = wrapped_callback(request, *callback_args, **callback_kwargs)
  File "./maindb/views.py", line 35, in basic_data
    a = make(request)
  File "./maindb/lib/check.py", line 26, in make
    if user_id in [x.id_m[0:len(user_id)] for x in ID.objects.all()]:
  File "/usr/local/lib/python3.6/dist-packages/django/db/models/query.py", line 268, in __iter__
    self._fetch_all()
  File "/usr/local/lib/python3.6/dist-packages/django/db/models/query.py", line 1186, in _fetch_all
    self._result_cache = list(self._iterable_class(self))
  File "/usr/local/lib/python3.6/dist-packages/django/db/models/query.py", line 54, in __iter__
    results = compiler.execute_sql(chunked_fetch=self.chunked_fetch, chunk_size=self.chunk_size)
  File "/usr/local/lib/python3.6/dist-packages/django/db/models/sql/compiler.py", line 1063, in execute_sql
    cursor = self.connection.cursor()
  File "/usr/local/lib/python3.6/dist-packages/django/db/backends/base/base.py", line 255, in cursor
    return self._cursor()
  File "/usr/local/lib/python3.6/dist-packages/django/db/backends/base/base.py", line 232, in _cursor
    self.ensure_connection()
  File "/usr/local/lib/python3.6/dist-packages/django/db/backends/base/base.py", line 216, in ensure_connection
    self.connect()
  File "/usr/local/lib/python3.6/dist-packages/django/db/utils.py", line 89, in __exit__
    raise dj_exc_value.with_traceback(traceback) from exc_value
  File "/usr/local/lib/python3.6/dist-packages/django/db/backends/base/base.py", line 216, in ensure_connection
    self.connect()
  File "/usr/local/lib/python3.6/dist-packages/django/db/backends/base/base.py", line 194, in connect
    self.connection = self.get_new_connection(conn_params)
  File "/usr/local/lib/python3.6/dist-packages/django/db/backends/postgresql/base.py", line 178, in get_new_connection
    connection = Database.connect(**conn_params)
  File "/usr/lib/python3/dist-packages/psycopg2/__init__.py", line 130, in connect
    conn = _connect(dsn, connection_factory=connection_factory, **kwasync)
django.db.utils.OperationalError: fe_sendauth: no password supplied

Internal Server Error: /back_end/basic_data/
Traceback (most recent call last):
  File "/usr/local/lib/python3.6/dist-packages/django/db/backends/base/base.py", line 216, in ensure_connection
    self.connect()
  File "/usr/local/lib/python3.6/dist-packages/django/db/backends/base/base.py", line 194, in connect
    self.connection = self.get_new_connection(conn_params)
  File "/usr/local/lib/python3.6/dist-packages/django/db/backends/postgresql/base.py", line 178, in get_new_connection
    connection = Database.connect(**conn_params)
  File "/usr/lib/python3/dist-packages/psycopg2/__init__.py", line 130, in connect
    conn = _connect(dsn, connection_factory=connection_factory, **kwasync)
psycopg2.OperationalError: fe_sendauth: no password supplied


The above exception was the direct cause of the following exception:

Traceback (most recent call last):
  File "/usr/local/lib/python3.6/dist-packages/django/core/handlers/exception.py", line 34, in inner
    response = get_response(request)
  File "/usr/local/lib/python3.6/dist-packages/django/core/handlers/base.py", line 126, in _get_response
    response = self.process_exception_by_middleware(e, request)
  File "/usr/local/lib/python3.6/dist-packages/django/core/handlers/base.py", line 124, in _get_response
    response = wrapped_callback(request, *callback_args, **callback_kwargs)
  File "./maindb/views.py", line 35, in basic_data
    a = make(request)
  File "./maindb/lib/check.py", line 26, in make
    if user_id in [x.id_m[0:len(user_id)] for x in ID.objects.all()]:
  File "/usr/local/lib/python3.6/dist-packages/django/db/models/query.py", line 268, in __iter__
    self._fetch_all()
  File "/usr/local/lib/python3.6/dist-packages/django/db/models/query.py", line 1186, in _fetch_all
    self._result_cache = list(self._iterable_class(self))
  File "/usr/local/lib/python3.6/dist-packages/django/db/models/query.py", line 54, in __iter__
    results = compiler.execute_sql(chunked_fetch=self.chunked_fetch, chunk_size=self.chunk_size)
  File "/usr/local/lib/python3.6/dist-packages/django/db/models/sql/compiler.py", line 1063, in execute_sql
    cursor = self.connection.cursor()
  File "/usr/local/lib/python3.6/dist-packages/django/db/backends/base/base.py", line 255, in cursor
    return self._cursor()
  File "/usr/local/lib/python3.6/dist-packages/django/db/backends/base/base.py", line 232, in _cursor
    self.ensure_connection()
  File "/usr/local/lib/python3.6/dist-packages/django/db/backends/base/base.py", line 216, in ensure_connection
    self.connect()
  File "/usr/local/lib/python3.6/dist-packages/django/db/utils.py", line 89, in __exit__
    raise dj_exc_value.with_traceback(traceback) from exc_value
  File "/usr/local/lib/python3.6/dist-packages/django/db/backends/base/base.py", line 216, in ensure_connection
    self.connect()
  File "/usr/local/lib/python3.6/dist-packages/django/db/backends/base/base.py", line 194, in connect
    self.connection = self.get_new_connection(conn_params)
  File "/usr/local/lib/python3.6/dist-packages/django/db/backends/postgresql/base.py", line 178, in get_new_connection
    connection = Database.connect(**conn_params)
  File "/usr/lib/python3/dist-packages/psycopg2/__init__.py", line 130, in connect
    conn = _connect(dsn, connection_factory=connection_factory, **kwasync)
django.db.utils.OperationalError: fe_sendauth: no password supplied

Internal Server Error: /back_end/basic_data/
Traceback (most recent call last):
  File "/usr/local/lib/python3.6/dist-packages/django/db/backends/base/base.py", line 216, in ensure_connection
    self.connect()
  File "/usr/local/lib/python3.6/dist-packages/django/db/backends/base/base.py", line 194, in connect
    self.connection = self.get_new_connection(conn_params)
  File "/usr/local/lib/python3.6/dist-packages/django/db/backends/postgresql/base.py", line 178, in get_new_connection
    connection = Database.connect(**conn_params)
  File "/usr/lib/python3/dist-packages/psycopg2/__init__.py", line 130, in connect
    conn = _connect(dsn, connection_factory=connection_factory, **kwasync)
psycopg2.OperationalError: fe_sendauth: no password supplied


The above exception was the direct cause of the following exception:

Traceback (most recent call last):
  File "/usr/local/lib/python3.6/dist-packages/django/core/handlers/exception.py", line 34, in inner
    response = get_response(request)
  File "/usr/local/lib/python3.6/dist-packages/django/core/handlers/base.py", line 126, in _get_response
    response = self.process_exception_by_middleware(e, request)
  File "/usr/local/lib/python3.6/dist-packages/django/core/handlers/base.py", line 124, in _get_response
    response = wrapped_callback(request, *callback_args, **callback_kwargs)
  File "./maindb/views.py", line 35, in basic_data
    a = make(request)
  File "./maindb/lib/check.py", line 26, in make
    if user_id in [x.id_m[0:len(user_id)] for x in ID.objects.all()]:
  File "/usr/local/lib/python3.6/dist-packages/django/db/models/query.py", line 268, in __iter__
    self._fetch_all()
  File "/usr/local/lib/python3.6/dist-packages/django/db/models/query.py", line 1186, in _fetch_all
    self._result_cache = list(self._iterable_class(self))
  File "/usr/local/lib/python3.6/dist-packages/django/db/models/query.py", line 54, in __iter__
    results = compiler.execute_sql(chunked_fetch=self.chunked_fetch, chunk_size=self.chunk_size)
  File "/usr/local/lib/python3.6/dist-packages/django/db/models/sql/compiler.py", line 1063, in execute_sql
    cursor = self.connection.cursor()
  File "/usr/local/lib/python3.6/dist-packages/django/db/backends/base/base.py", line 255, in cursor
    return self._cursor()
  File "/usr/local/lib/python3.6/dist-packages/django/db/backends/base/base.py", line 232, in _cursor
    self.ensure_connection()
  File "/usr/local/lib/python3.6/dist-packages/django/db/backends/base/base.py", line 216, in ensure_connection
    self.connect()
  File "/usr/local/lib/python3.6/dist-packages/django/db/utils.py", line 89, in __exit__
    raise dj_exc_value.with_traceback(traceback) from exc_value
  File "/usr/local/lib/python3.6/dist-packages/django/db/backends/base/base.py", line 216, in ensure_connection
    self.connect()
  File "/usr/local/lib/python3.6/dist-packages/django/db/backends/base/base.py", line 194, in connect
    self.connection = self.get_new_connection(conn_params)
  File "/usr/local/lib/python3.6/dist-packages/django/db/backends/postgresql/base.py", line 178, in get_new_connection
    connection = Database.connect(**conn_params)
  File "/usr/lib/python3/dist-packages/psycopg2/__init__.py", line 130, in connect
    conn = _connect(dsn, connection_factory=connection_factory, **kwasync)
django.db.utils.OperationalError: fe_sendauth: no password supplied

Internal Server Error: /back_end/basic_data/
Traceback (most recent call last):
  File "/usr/local/lib/python3.6/dist-packages/django/db/backends/base/base.py", line 216, in ensure_connection
    self.connect()
  File "/usr/local/lib/python3.6/dist-packages/django/db/backends/base/base.py", line 194, in connect
    self.connection = self.get_new_connection(conn_params)
  File "/usr/local/lib/python3.6/dist-packages/django/db/backends/postgresql/base.py", line 178, in get_new_connection
    connection = Database.connect(**conn_params)
  File "/usr/lib/python3/dist-packages/psycopg2/__init__.py", line 130, in connect
    conn = _connect(dsn, connection_factory=connection_factory, **kwasync)
psycopg2.OperationalError: fe_sendauth: no password supplied


The above exception was the direct cause of the following exception:

Traceback (most recent call last):
  File "/usr/local/lib/python3.6/dist-packages/django/core/handlers/exception.py", line 34, in inner
    response = get_response(request)
  File "/usr/local/lib/python3.6/dist-packages/django/core/handlers/base.py", line 126, in _get_response
    response = self.process_exception_by_middleware(e, request)
  File "/usr/local/lib/python3.6/dist-packages/django/core/handlers/base.py", line 124, in _get_response
    response = wrapped_callback(request, *callback_args, **callback_kwargs)
  File "./maindb/views.py", line 35, in basic_data
    a = make(request)
  File "./maindb/lib/check.py", line 26, in make
    if user_id in [x.id_m[0:len(user_id)] for x in ID.objects.all()]:
  File "/usr/local/lib/python3.6/dist-packages/django/db/models/query.py", line 268, in __iter__
    self._fetch_all()
  File "/usr/local/lib/python3.6/dist-packages/django/db/models/query.py", line 1186, in _fetch_all
    self._result_cache = list(self._iterable_class(self))
  File "/usr/local/lib/python3.6/dist-packages/django/db/models/query.py", line 54, in __iter__
    results = compiler.execute_sql(chunked_fetch=self.chunked_fetch, chunk_size=self.chunk_size)
  File "/usr/local/lib/python3.6/dist-packages/django/db/models/sql/compiler.py", line 1063, in execute_sql
    cursor = self.connection.cursor()
  File "/usr/local/lib/python3.6/dist-packages/django/db/backends/base/base.py", line 255, in cursor
    return self._cursor()
  File "/usr/local/lib/python3.6/dist-packages/django/db/backends/base/base.py", line 232, in _cursor
    self.ensure_connection()
  File "/usr/local/lib/python3.6/dist-packages/django/db/backends/base/base.py", line 216, in ensure_connection
    self.connect()
  File "/usr/local/lib/python3.6/dist-packages/django/db/utils.py", line 89, in __exit__
    raise dj_exc_value.with_traceback(traceback) from exc_value
  File "/usr/local/lib/python3.6/dist-packages/django/db/backends/base/base.py", line 216, in ensure_connection
    self.connect()
  File "/usr/local/lib/python3.6/dist-packages/django/db/backends/base/base.py", line 194, in connect
    self.connection = self.get_new_connection(conn_params)
  File "/usr/local/lib/python3.6/dist-packages/django/db/backends/postgresql/base.py", line 178, in get_new_connection
    connection = Database.connect(**conn_params)
  File "/usr/lib/python3/dist-packages/psycopg2/__init__.py", line 130, in connect
    conn = _connect(dsn, connection_factory=connection_factory, **kwasync)
django.db.utils.OperationalError: fe_sendauth: no password supplied

Not Found: /
Not Found: /
Not Found: /favicon.ico
